<?xml version="1.0"?>
<robot xmlns:xacro="http://ros.org/wiki/xacro" name="racecar_hinge">
    <xacro:macro name="racecar_hinge" params="namespace hinge_prefix *joint_pose">
        <link name="${namespace}${hinge_prefix}_hinge_link">
            <inertial>
                <origin xyz="0 0 0" rpy="0 0 0" />
                <mass value="0.100" />
                <inertia ixx="4E-06" ixy="0"      ixz="0"
                                     iyy="4E-06"  iyz="0"
                                                  izz="4E-06" />
            </inertial>
            <visual>
                <origin xyz="0 0 0" rpy="0 0 0" />
                <geometry>
                    <mesh filename="package://racecar_description/meshes/steering_hinge.STL" />
                </geometry>
            </visual>
        </link>
        
        <joint name="${namespace}${hinge_prefix}_hinge" type="continuous">
            <parent link="${namespace}base_link"/>
            <child link="${namespace}${hinge_prefix}_hinge_link"/>
            <xacro:insert_block name="joint_pose"/>
            <axis xyz="0 0 1" rpy="0 0 0" />
        </joint>
        
        <transmission name="${namespace}${hinge_prefix}_hinge_trans" type="SimpleTransmission">
            <type>transmission_interface/SimpleTransmission</type>
            <actuator name="${namespace}${hinge_prefix}_hinge_motor">
                <hardwareInterface>EffortJointInterface</hardwareInterface>
                <mechanicalReduction>1</mechanicalReduction>
            </actuator>
            <joint name="${namespace}${hinge_prefix}_hinge">
                <hardwareInterface>hardware_interface/EffortJointInterface</hardwareInterface>
            </joint>
       </transmission>

    </xacro:macro>
</robot>
