<?xml version="1.0"?>
<robot xmlns:xacro="http://ros.org/wiki/xacro" name="racecar_hinge">
    <xacro:macro name="racecar_hinge" params="namespace hinge_prefix *joint_pose">
        <link name="${namespace}${hinge_prefix}_hinge_link">
            <inertial>
                <origin xyz="0 0 0" rpy="0 0 0" />
                <mass value="1.00" />
                <inertia ixx="0.1" ixy="0"      ixz="0"
                                     iyy="0.1"  iyz="0"
                                                  izz="0.1" />
            </inertial>
            <visual>
                <origin xyz="0 0 0" rpy="0 0 0" />
                <geometry>
                    <mesh filename="package://racecar_description/meshes/steering_hinge.STL" />
                </geometry>
            </visual>
        </link>
        
        <joint name="${namespace}${hinge_prefix}_hinge" type="revolute">
            <parent link="${namespace}base_link"/>
            <child link="${namespace}${hinge_prefix}_hinge_link"/>
            <xacro:insert_block name="joint_pose"/>
            <axis xyz="0 0 1"/>
            <limit upper="3.14" lower="-3.14" effort="1000.0" velocity="50.0" />
        </joint>
        
        <transmission name="${namespace}${hinge_prefix}_hinge_trans" type="SimpleTransmission">
            <type>transmission_interface/SimpleTransmission</type>
            <actuator name="${namespace}${hinge_prefix}_hinge_motor">
                <hardwareInterface>PositionJointInterface</hardwareInterface>
                <mechanicalReduction>1</mechanicalReduction>
            </actuator>
            <joint name="${namespace}${hinge_prefix}_hinge">
                <hardwareInterface>hardware_interface/PositionJointInterface</hardwareInterface>
            </joint>
       </transmission>

    </xacro:macro>
</robot>
