<?xml version="1.0"?>
<robot xmlns:xacro="http://ros.org/wiki/xacro" name="racecar_wheel">
    <xacro:macro name="racecar_wheel" params="namespace wheel_prefix parent is_motor *joint_pose">
        <link name="${namespace}${wheel_prefix}_wheel_link">
            <inertial>
                <mass value="0.3" />
                <origin xyz="0 0 0" />
                <inertia ixx="${0.3/12*(3*wheel_radius*wheel_radius + wheel_length*wheel_length)}" ixy="0"           ixz="0"
                         iyy="${0.3/12*(3*wheel_radius*wheel_radius + wheel_length*wheel_length)}"   iyz="0"
                         izz="${0.3/2 * wheel_radius*wheel_radius}" />
            </inertial>
            <visual>
                <origin xyz="0 0 0" rpy="${M_PI/2} 0 0" />
                <geometry>
                    <cylinder length="${wheel_length}" radius="${wheel_radius}" />
                </geometry>
            </visual>
            <collision>
                <origin xyz="0 0 0" rpy="${M_PI/2} 0 0" />
                <geometry>
                    <cylinder length="${wheel_length}" radius="${wheel_radius}" />
                </geometry>
            </collision>
        </link>

        <gazebo reference="${namespace}${wheel_prefix}_wheel_link">
            <mu1 value="1.5"/>
            <mu2 value="1.5"/>
            <kp value="10000000.0" />
            <kd value="1.0" />
            <fdir1 value="1 0 0"/>
            <material>Gazebo/Black</material>
        </gazebo>

        <joint name="${namespace}${wheel_prefix}_wheel" type="continuous">
            <parent link="${namespace}${parent}"/>
            <child link="${namespace}${wheel_prefix}_wheel_link"/>
            <xacro:insert_block name="joint_pose"/>
            <axis xyz="0 1 0" rpy="0 0 0" />
            <limit effort="100" velocity="400" />
        </joint>

        <xacro:if value="${is_motor}">
            <transmission name="${namespace}${wheel_prefix}_wheel_trans" type="SimpleTransmission">
                <type>transmission_interface/SimpleTransmission</type>
                <actuator name="${namespace}${wheel_prefix}_wheel_motor">
                    <hardwareInterface>hardware_interface/VelocityJointInterface</hardwareInterface>
                    <mechanicalReduction>1</mechanicalReduction>
                </actuator>
                <joint name="${namespace}${wheel_prefix}_wheel">
                    <hardwareInterface>hardware_interface/VelocityJointInterface</hardwareInterface>
                </joint>
            </transmission>
        </xacro:if>

    </xacro:macro>
</robot>
